{
  "comments": [
    {
      "key": {
        "uuid": "AAAAUH/+2QI\u003d",
        "filename": "nodepool/nodepool.py",
        "patchSetId": 4
      },
      "lineNbr": 285,
      "author": {
        "id": 5263
      },
      "writtenOn": "2014-01-21T13:38:16Z",
      "side": 1,
      "message": "If we\u0027re just punting these to the periodic cleanup queue, the reason for this inner try/except block has probably vaporized.",
      "revId": "b2861e52e52e625d79d76e3c72686c4c20ab2694",
      "serverId": "4a232e18-c5a9-48ee-94c0-e04e7cca6543",
      "unresolved": false
    }
  ]
}